<?xml version="1.0"?>
<robot name="arm">

  <link name="base_link">
    <visual>
      <geometry>
        <box size="0.088 0.090 0.029"/>
      </geometry> 
      <origin rpy="0 0 0" xyz="0 0 0"/>
    </visual>
    <collision>
      <geometry>
        <box size="0.088 0.090 0.029"/>
      </geometry> 
      <origin rpy="0 0 0" xyz="0 0 0"/>
    </collision>
  </link>

  <link name="base_up">
    <visual>
      <geometry>
        <box size="0.059 0.026 0.054"/>
      </geometry>
      <origin rpy="0 0 0" xyz="0 0 0"/>
    </visual>
    <collision>
      <geometry>
        <box size="0.059 0.026 0.054"/>
      </geometry>
      <origin rpy="0 0 0" xyz="0 0 0"/>
    </collision>
  </link>

  <joint name="baseup_link" type="fixed">
    <parent link="base_link"/>
    <child link="base_up"/>
    <origin xyz="0.0155 0 0.0415"/>
  </joint>

  <link name="servo_rotz">
    <visual>
      <geometry>
        <box size="0.058 0.060 0.025"/>
      </geometry>
      <origin rpy="0 0 0" xyz="0 -0.013 0"/>
    </visual>
    <collision>
      <geometry>
        <box size="0.058 0.060 0.025"/>
      </geometry>
      <origin rpy="0 0 0" xyz="0 -0.013 0"/>
    </collision>
  </link>

  <joint name="servo_link2" type="revolute">
    <axis xyz="0 0 1"/>
    <limit effort="1000.0" lower="-1.57" upper="1.57" velocity="0.5"/>
    <parent link="base_up"/>
    <child link="servo_rotz"/>
    <origin xyz="0.0095 0 0.0395"/>
  </joint>

  <link name="connection_servo12">
    <visual>
      <geometry>
        <box size="0.13 0.06 0.026"/>
      </geometry>
      <origin rpy="0 0 0" xyz="-0.052 0 0"/>
    </visual>
    <collision>
      <geometry>
        <box size="0.13 0.06 0.026"/>
      </geometry>
      <origin rpy="0 0 0" xyz="-0.052 0 0"/>
    </collision>
  </link>

  <joint name="con_up_1" type="revolute">
    <axis xyz="0 1 0"/>
    <limit effort="1000.0" lower="-1.57" upper="1.57" velocity="0.5"/>
    <parent link="servo_rotz"/>
    <child link="connection_servo12"/>
    <origin xyz="-0.009 -0.013 0"/>
  </joint>


  <link name="connection_servo23">
    <visual>
      <geometry>
        <box size="0.130 0.060 0.055"/>
      </geometry>
      <origin rpy="0 0 0" xyz="-0.047 0 0.0145"/>
    </visual>
    <collision>
      <geometry>
        <box size="1.30 0.60 0.55"/>
      </geometry>
      <origin rpy="0 0 0" xyz="-0.047 0 0.0145"/>
    </collision>
  </link>

  <joint name="con_up_2" type="revolute">
    <axis xyz="0 1 0"/>
    <limit effort="1000.0" lower="-1.57" upper="1.57" velocity="0.5"/>
    <parent link="connection_servo12"/>
    <child link="connection_servo23"/>
    <origin xyz="-0.104 0 0"/>
  </joint>

  <link name="servo_arm_rotation">
    <visual>
      <geometry>
        <box size="0.085 0.060 0.025 "/>
      </geometry>
      <origin rpy="0 0 0" xyz="-0.0295 0 0"/>
    </visual>
    <collision>
      <geometry>
        <box size="0.085 0.060 0.025 "/>
      </geometry>
      <origin rpy="0 0 0" xyz="-0.0295 0 0"/>
    </collision>
  </link>

 <joint name="con_up_3" type="revolute">
    <axis xyz="0 1 0"/>
    <limit effort="1000.0" lower="-1.57" upper="1.57" velocity="0.5"/>
    <parent link="connection_servo23"/>
    <child link="servo_arm_rotation"/>
    <origin xyz="-0.094 0 0"/>
  </joint>

  <link name="gripper_b">
    <visual>
      <geometry>
        <box size="0.050 0.072 0.052"/>
      </geometry>
      <origin rpy="0 0 0" xyz="-0.025 -0.019 0.014"/>
    </visual>
    <collision>
      <geometry>
        <box size="0.050 0.072 0.052"/>
      </geometry>
      <origin rpy="0 0 0" xyz="-0.025 -0.019 0.014"/>
    </collision>
  </link>

 <joint name="rotation_grip" type="revolute">
    <axis xyz="1 0 0"/>
    <limit effort="1000.0" lower="0" upper="3.14" velocity="0.5"/>
    <parent link="servo_arm_rotation"/>
    <child link="gripper_b"/>
    <origin xyz="-0.072 0.013 0"/>
  </joint>

  <link name="left_g">
    <visual>
      <geometry>
        <box size="0.037 0.019 0.020"/>
      </geometry>
      <origin rpy="0 0 0" xyz="0 0 0"/>
    </visual>
    <collision>
      <geometry>
        <box size="0.037 0.019 0.020"/>
      </geometry>
      <origin rpy="0 0 0" xyz="0 0 0"/>
    </collision>
  </link>

 <joint name="fix_left" type="fixed">
    <parent link="gripper_b"/>
    <child link="left_g"/>
    <origin xyz="-0.068 -0.038 0"/>
  </joint>

  <link name="right_g">
    <visual>
      <geometry>
        <box size="0.037 0.019 0.020"/>
      </geometry>
      <origin rpy="0 0 0" xyz="0 0 0"/>
    </visual>
    <collision>
      <geometry>
        <box size="0.037 0.019 0.020"/>
      </geometry>
      <origin rpy="0 0 0" xyz="0 0 0"/>
    </collision>
  </link>

 <joint name="plan_move" type="prismatic">
    <axis xyz="0 1 0"/>
    <limit effort="1000.0" lower="0" upper="0.053" velocity="0.5"/>
    <parent link="left_g"/>
    <child link="right_g"/>
    <origin xyz="0 0.019 0"/>
  </joint>

<!-- -->
</robot>