<?xml version="1.0" ?>
<!-- =================================================================================== -->
<!-- |    This document was autogenerated by xacro from description/urdf/braccio.urdf.xacro | -->
<!-- |    EDITING THIS FILE BY HAND IS NOT RECOMMENDED                                 | -->
<!-- =================================================================================== -->
<robot name="braccio">
  <!-- create link fixed to the "world" -->
  <link name="world"/>
  <!-- Load the YAML file -->
  <!-- <xacro:property name="yaml_file" value="$(find braccio_simulation)/urdf/config/braccio_param.yaml"/>
    <xacro:property name="robot_descr" value="${xacro.load_yaml(yaml_file)}"/> -->
  <!-- helper macro -->
  <link name="base_link">
    <visual>
      <origin rpy="0 0 0" xyz="0 0 0.0145"/>
      <geometry>
        <box size="0.088 0.090 0.029"/>
      </geometry>
    </visual>
    <collision>
      <origin rpy="0 0 0" xyz="0 0 0.0145"/>
      <geometry>
        <box size="0.088 0.090 0.029"/>
      </geometry>
    </collision>
    <inertial>
      <mass value="1"/>
      <inertia ixx="1.0" ixy="0.0" ixz="0.0" iyy="1.0" iyz="0.0" izz="1.0"/>
    </inertial>
  </link>
  <link name="base_vert_servo_rot">
    <visual>
      <origin rpy="0 0 0" xyz="0 0 0"/>
      <geometry>
        <box size="0.059 0.026 0.050"/>
      </geometry>
    </visual>
    <collision>
      <origin rpy="0 0 0" xyz="0 0 0"/>
      <geometry>
        <box size="0.059 0.026 0.050"/>
      </geometry>
    </collision>
    <inertial>
      <mass value="1"/>
      <inertia ixx="1.0" ixy="0.0" ixz="0.0" iyy="1.0" iyz="0.0" izz="1.0"/>
    </inertial>
  </link>
  <link name="base_servo_ud">
    <visual>
      <origin rpy="0 0 0" xyz="0.002 0.012 0.013"/>
      <geometry>
        <box size="0.058 0.050 0.026"/>
      </geometry>
    </visual>
    <collision>
      <origin rpy="0 0 0" xyz="0.002 0.012 0.013"/>
      <geometry>
        <box size="0.058 0.050 0.026"/>
      </geometry>
    </collision>
    <inertial>
      <mass value="1"/>
      <inertia ixx="1.0" ixy="0.0" ixz="0.0" iyy="1.0" iyz="0.0" izz="1.0"/>
    </inertial>
  </link>
  <link name="arm_1_up_down_p1">
    <visual>
      <origin rpy="0 0 -1.570796327" xyz="0 0 0"/>
      <geometry>
        <mesh filename="file:///braccio_control/install/braccio_simulation/share/braccio_simulation/model/3Dparts/ModelARM-Body.stl" scale="0.001 0.001 0.001"/>
      </geometry>
    </visual>
    <collision>
      <origin rpy="0 0 -1.570796327" xyz="0 0 0"/>
      <geometry>
        <mesh filename="file:///braccio_control/install/braccio_simulation/share/braccio_simulation/model/3Dparts/ModelARM-Body.stl" scale="0.001 0.001 0.001"/>
      </geometry>
    </collision>
    <inertial>
      <mass value="1"/>
      <inertia ixx="1.0" ixy="0.0" ixz="0.0" iyy="1.0" iyz="0.0" izz="1.0"/>
    </inertial>
  </link>
  <link name="arm_1_up_down_p2">
    <visual>
      <origin rpy="3.141592653589793 0 -1.570796327" xyz="0 0 0"/>
      <geometry>
        <mesh filename="file:///braccio_control/install/braccio_simulation/share/braccio_simulation/model/3Dparts/ModelARM-Body.stl" scale="0.001 0.001 0.001"/>
      </geometry>
    </visual>
    <collision>
      <origin rpy="3.141592653589793 0 -1.570796327" xyz="0 0 0"/>
      <geometry>
        <mesh filename="file:///braccio_control/install/braccio_simulation/share/braccio_simulation/model/3Dparts/ModelARM-Body.stl" scale="0.001 0.001 0.001"/>
      </geometry>
    </collision>
    <inertial>
      <mass value="1"/>
      <inertia ixx="1.0" ixy="0.0" ixz="0.0" iyy="1.0" iyz="0.0" izz="1.0"/>
    </inertial>
  </link>
  <link name="arm_2_up_down">
    <visual>
      <origin rpy="0 0 0" xyz="0.045 -0.001 0"/>
      <geometry>
        <box size="0.13 0.050 0.028"/>
      </geometry>
    </visual>
    <collision>
      <origin rpy="0 0 0" xyz="0.045 -0.001 0"/>
      <geometry>
        <box size="0.13 0.050 0.028"/>
      </geometry>
    </collision>
    <inertial>
      <mass value="1"/>
      <inertia ixx="1.0" ixy="0.0" ixz="0.0" iyy="1.0" iyz="0.0" izz="1.0"/>
    </inertial>
  </link>
  <link name="arm_3_up_down">
    <visual>
      <origin rpy="0 0 -1.570796327" xyz="0 0 0"/>
      <geometry>
        <mesh filename="file:///braccio_control/install/braccio_simulation/share/braccio_simulation/model/3Dparts/ModelARM-Body.stl" scale="0.001 0.001 0.001"/>
      </geometry>
    </visual>
    <collision>
      <origin rpy="0 0 -1.570796327" xyz="0 0 0"/>
      <geometry>
        <mesh filename="file:///braccio_control/install/braccio_simulation/share/braccio_simulation/model/3Dparts/ModelARM-Body.stl" scale="0.001 0.001 0.001"/>
      </geometry>
    </collision>
    <inertial>
      <mass value="1"/>
      <inertia ixx="1.0" ixy="0.0" ixz="0.0" iyy="1.0" iyz="0.0" izz="1.0"/>
    </inertial>
  </link>
  <link name="box_servo_rot">
    <visual>
      <origin rpy="0 0 0" xyz="0 0 0"/>
      <geometry>
        <box size="0.042 0.042 0.021"/>
      </geometry>
    </visual>
    <collision>
      <origin rpy="0 0 0" xyz="0 0 0"/>
      <geometry>
        <box size="0.042 0.042 0.021"/>
      </geometry>
    </collision>
    <inertial>
      <mass value="1"/>
      <inertia ixx="1.0" ixy="0.0" ixz="0.0" iyy="1.0" iyz="0.0" izz="1.0"/>
    </inertial>
  </link>
  <link name="rot_grasp">
    <visual>
      <origin rpy="0 0 0" xyz="0.0265 0 0"/>
      <geometry>
        <box size="0.053 0.055 0.019"/>
      </geometry>
    </visual>
    <collision>
      <origin rpy="0 0 0" xyz="0.0265 0 0"/>
      <geometry>
        <box size="0.053 0.055 0.019"/>
      </geometry>
    </collision>
    <inertial>
      <mass value="1"/>
      <inertia ixx="1.0" ixy="0.0" ixz="0.0" iyy="1.0" iyz="0.0" izz="1.0"/>
    </inertial>
  </link>
  <link name="grasp_box">
    <visual>
      <origin rpy="0 0 0" xyz="0.03 0.025 0.0165"/>
      <geometry>
        <box size="0.020 0.050 0.033"/>
      </geometry>
    </visual>
    <collision>
      <origin rpy="0 0 0" xyz="0.03 0.025 0.0165"/>
      <geometry>
        <box size="0.020 0.050 0.033"/>
      </geometry>
    </collision>
    <inertial>
      <mass value="1"/>
      <inertia ixx="1.0" ixy="0.0" ixz="0.0" iyy="1.0" iyz="0.0" izz="1.0"/>
    </inertial>
  </link>
  <link name="grasp_l">
    <visual>
      <origin rpy="0 0 0" xyz="0.029 0.005 0"/>
      <geometry>
        <box size="0.058 0.010 0.020"/>
      </geometry>
    </visual>
    <collision>
      <origin rpy="0 0 0" xyz="0.029 0.005 0"/>
      <geometry>
        <box size="0.058 0.010 0.020"/>
      </geometry>
    </collision>
    <inertial>
      <mass value="1"/>
      <inertia ixx="1.0" ixy="0.0" ixz="0.0" iyy="1.0" iyz="0.0" izz="1.0"/>
    </inertial>
  </link>
  <link name="grasp_r">
    <visual>
      <origin rpy="0 0 0" xyz="0.029 -0.005 0"/>
      <geometry>
        <box size="0.058 0.010 0.020"/>
      </geometry>
    </visual>
    <collision>
      <origin rpy="0 0 0" xyz="0.029 -0.005 0"/>
      <geometry>
        <box size="0.058 0.010 0.020"/>
      </geometry>
    </collision>
    <inertial>
      <mass value="1"/>
      <inertia ixx="1.0" ixy="0.0" ixz="0.0" iyy="1.0" iyz="0.0" izz="1.0"/>
    </inertial>
  </link>
  <joint name="world_joint" type="fixed">
    <parent link="world"/>
    <child link="base_link"/>
    <origin rpy="0 0 0" xyz="0 0 0"/>
  </joint>
  <joint name="baseup_link" type="fixed">
    <parent link="base_link"/>
    <child link="base_vert_servo_rot"/>
    <origin xyz="-0.0145 0 0.054"/>
  </joint>
  <joint name="arm_rot" type="revolute">
    <axis xyz="0 0 1"/>
    <limit effort="1000.0" lower="-1.570796327" upper="1.570796327" velocity="0.5"/>
    <parent link="base_vert_servo_rot"/>
    <child link="base_servo_ud"/>
    <origin xyz="-0.012 0 0.025"/>
  </joint>
  <joint name="arm_1_up_down" type="revolute">
    <axis xyz="0 1 0"/>
    <limit effort="1000.0" lower="-1.570796327" upper="1.570796327" velocity="0.5"/>
    <parent link="base_servo_ud"/>
    <child link="arm_1_up_down_p1"/>
    <origin xyz="0.011 0.013 0.014"/>
  </joint>
  <joint name="arm_1_up_down_2" type="fixed">
    <parent link="arm_1_up_down_p1"/>
    <child link="arm_1_up_down_p2"/>
    <origin xyz="0.106 0.0 0.0"/>
  </joint>
  <joint name="arm_2_up_down" type="revolute">
    <axis xyz="0 1 0"/>
    <limit effort="1000.0" lower="-1.570796327" upper="1.570796327" velocity="0.5"/>
    <parent link="arm_1_up_down_p2"/>
    <child link="arm_2_up_down"/>
    <origin xyz="0.0 0.0 0"/>
  </joint>
  <joint name="arm_3_up_down" type="revolute">
    <axis xyz="0 1 0"/>
    <limit effort="1000.0" lower="-1.570796327" upper="1.570796327" velocity="0.5"/>
    <parent link="arm_2_up_down"/>
    <child link="arm_3_up_down"/>
    <origin xyz="0.091 0 0"/>
  </joint>
  <joint name="supServoRot" type="fixed">
    <parent link="arm_3_up_down"/>
    <child link="box_servo_rot"/>
    <origin xyz="0.042 0 0"/>
  </joint>
  <joint name="rot_grasp" type="revolute">
    <axis xyz="1 0 0"/>
    <limit effort="1000.0" lower="-1.570796327" upper="1.570796327" velocity="0.5"/>
    <parent link="box_servo_rot"/>
    <child link="rot_grasp"/>
    <origin xyz="0.028 -0.011 0"/>
  </joint>
  <joint name="rotation_grip" type="fixed">
    <parent link="rot_grasp"/>
    <child link="grasp_box"/>
    <origin xyz="0 0 0"/>
  </joint>
  <joint name="grasp" type="prismatic">
    <axis xyz="0 1 0"/>
    <limit effort="1000" lower="0" upper="0.03" velocity="2.0"/>
    <parent link="rot_grasp"/>
    <child link="grasp_l"/>
    <origin xyz="0.052 0 0"/>
  </joint>
  <joint name="plan_move" type="prismatic">
    <axis xyz="0 -1 0"/>
    <limit effort="1000" lower="0" upper="0.03" velocity="2.0"/>
    <parent link="rot_grasp"/>
    <child link="grasp_r"/>
    <origin xyz="0.052 0 0"/>
    <mimic joint="grasp" multiplier="1" offset="0"/>
  </joint>
  <ros2_control name="braccio" type="system">
    <hardware>
      <plugin>ros2_control_braccio/RobotSystem</plugin>
    </hardware>
    <joint name="arm_rot">
      <command_interface name="position">
        <param name="min">-6.283185307179586</param>
        <param name="max">6.283185307179586</param>
      </command_interface>
      <state_interface name="position">
        <param name="initial_value">0.0</param>
      </state_interface>
    </joint>
    <joint name="arm_1_up_down">
      <command_interface name="position">
        <param name="min">-6.283185307179586</param>
        <param name="max">6.283185307179586</param>
      </command_interface>
      <state_interface name="position">
        <param name="initial_value">0.0</param>
      </state_interface>
    </joint>
    <joint name="arm_2_up_down">
      <command_interface name="position">
        <param name="min">-3.141592653589793</param>
        <param name="max">3.141592653589793</param>
      </command_interface>
      <state_interface name="position">
        <param name="initial_value">0.0</param>
      </state_interface>
    </joint>
    <joint name="arm_3_up_down">
      <command_interface name="position">
        <param name="min">-6.283185307179586</param>
        <param name="max">6.283185307179586</param>
      </command_interface>
      <state_interface name="position">
        <param name="initial_value">0.0</param>
      </state_interface>
    </joint>
    <joint name="rot_grasp">
      <command_interface name="position">
        <param name="min">-6.283185307179586</param>
        <param name="max">6.283185307179586</param>
      </command_interface>
      <state_interface name="position">
        <param name="initial_value">0.0</param>
      </state_interface>
    </joint>
    <joint name="grasp">
      <command_interface name="position">
        <param name="min">-6.283185307179586</param>
        <param name="max">6.283185307179586</param>
      </command_interface>
      <state_interface name="position">
        <param name="initial_value">0.0</param>
      </state_interface>
    </joint>
  </ros2_control>
</robot>
